Workbook

Sheet README
A1: RAB Consulting Services - PHI & ITSM Consultant Workbook
A2: Working assessment tool for live use while the website platform is being developed.
A4: Purpose | B4: Use this workbook to run client-facing snapshots and full consultant-led assessments for PHI and ITSM-HI.
A5: How to use | B5: Complete only blue cells. Review the linked dashboard sheet after scoring. Use the AI prompt sheets if you want a draft narrative.
A6: Scoring | B6: 1 Critical failure / not in place | 2 Weak / inconsistent | 3 Partially controlled / at risk | 4 Controlled | 5 Strong / fully embedded
A7: Public snapshots | B7: PHI Snapshot and ITSM Snapshot are high-level lead diagnostics. Keep the result indicative and then offer a paid full review.
A8: Full assessments | B8: PHI Full and ITSM Full are consultant-only sheets with evidence notes, source type, confidence and summary dashboards.
A9: Key outputs | B9: PHI Full: Overall Score, RAG, BRI, VRI and Critical Flag. ITSM Full: Overall Score, RAG, SSI, SMI, BAU Readiness and Critical Flag.

Sheet Config
A1: Config
A2: Keep thresholds aligned to the website build.
A4: Score | B4: Label
A5: 1 | B5: Critical
A6: 2 | B6: Weak
A7: 3 | B7: At Risk
A8: 4 | B8: Controlled
A9: 5 | B9: Strong
A11: Threshold | B11: Value | C11: Meaning
A12: Red below | B12: 2.5 | C12: Immediate risk
A13: Amber below | B13: 3.8 | C13: At risk / partial control
A14: Green minimum | B14: 3.8 | C14: Controlled

Sheet PHI Snapshot
A1: Programme Health Check (PHI Snapshot)
A2: Public-facing lead diagnostic. Use only blue cells for input.
A4: Client / Assessor Name | B4: rayan | J4: Assessment Summary
A5: Job Title | B5: Director | J5: Overall Score | K5: =IF(COUNT(E15:E32)=0,"",ROUND(AVERAGE(E15:E32),2)) -> 3.67
A6: Company | B6: RRC CO | J6: RAG Status | K6: =IF(K5="","",IF(K5<2.5,"Red",IF(K5<3.8,"Amber","Green"))) -> Amber
A7: Programme / Project Name | B7: testrag | J7: Pillar Scores | K7: Score | L7: RAG
A8: Programme Type | B8: Finance Transformation | J8: Governance & Control | K8: =IF(COUNTIFS($B$15:$B$32,"P1",$E$15:$E$32,">0")=0,"",ROUND(SUMIF($B$15:$B$32,"P1",$E$15:$E$32)/COUNTIFS($B$15:$B$32,"P1",$E$15:$E$32,">0"),2)) -> 3 | L8: =IF(K8="","",IF(K8<2.5,"Red",IF(K8<3.8,"Amber","Green"))) -> Amber
A9: Delivery Stage | B9: Design | J9: Planning & Delivery | K9: =IF(COUNTIFS($B$15:$B$32,"P2",$E$15:$E$32,">0")=0,"",ROUND(SUMIF($B$15:$B$32,"P2",$E$15:$E$32)/COUNTIFS($B$15:$B$32,"P2",$E$15:$E$32,">0"),2)) -> 4 | L9: =IF(K9="","",IF(K9<2.5,"Red",IF(K9<3.8,"Amber","Green"))) -> Green
A10: Primary Concern | J10: Business Alignment | K10: =IF(COUNTIFS($B$15:$B$32,"P3",$E$15:$E$32,">0")=0,"",ROUND(SUMIF($B$15:$B$32,"P3",$E$15:$E$32)/COUNTIFS($B$15:$B$32,"P3",$E$15:$E$32,">0"),2)) -> 3 | L10: =IF(K10="","",IF(K10<2.5,"Red",IF(K10<3.8,"Amber","Green"))) -> Amber
A11: Scoring guide | B11: 1 Critical | 2 Weak | 3 At Risk | 4 Controlled | 5 Strong | J11: Change & Adoption | K11: =IF(COUNTIFS($B$15:$B$32,"P4",$E$15:$E$32,">0")=0,"",ROUND(SUMIF($B$15:$B$32,"P4",$E$15:$E$32)/COUNTIFS($B$15:$B$32,"P4",$E$15:$E$32,">0"),2)) -> 3 | L11: =IF(K11="","",IF(K11<2.5,"Red",IF(K11<3.8,"Amber","Green"))) -> Amber
J12: Data Readiness | K12: =IF(COUNTIFS($B$15:$B$32,"P5",$E$15:$E$32,">0")=0,"",ROUND(SUMIF($B$15:$B$32,"P5",$E$15:$E$32)/COUNTIFS($B$15:$B$32,"P5",$E$15:$E$32,">0"),2)) -> 4 | L12: =IF(K12="","",IF(K12<2.5,"Red",IF(K12<3.8,"Amber","Green"))) -> Green
J13: Solution & Process Fit | K13: =IF(COUNTIFS($B$15:$B$32,"P6",$E$15:$E$32,">0")=0,"",ROUND(SUMIF($B$15:$B$32,"P6",$E$15:$E$32)/COUNTIFS($B$15:$B$32,"P6",$E$15:$E$32,">0"),2)) -> 4 | L13: =IF(K13="","",IF(K13<2.5,"Red",IF(K13<3.8,"Amber","Green"))) -> Green
A14: Question ID | B14: Pillar Code | C14: Pillar | D14: Question | E14: Score | F14: Status | G14: Notes / Context | J14: Cutover & Go-Live | K14: =IF(COUNTIFS($B$15:$B$32,"P7",$E$15:$E$32,">0")=0,"",ROUND(SUMIF($B$15:$B$32,"P7",$E$15:$E$32)/COUNTIFS($B$15:$B$32,"P7",$E$15:$E$32,">0"),2)) -> 4 | L14: =IF(K14="","",IF(K14<2.5,"Red",IF(K14<3.8,"Amber","Green"))) -> Green
A15: P1_Q1 | B15: P1 | C15: Governance & Control | D15: Decision-making and escalation are clear and effective | E15: 3 | F15: =IF(E15="","",IF(E15=1,"Critical",IF(E15=2,"Weak",IF(E15=3,"At Risk",IF(E15=4,"Controlled","Strong"))))) -> At Risk | J15: Delivery Capability | K15: =IF(COUNTIFS($B$15:$B$32,"P8",$E$15:$E$32,">0")=0,"",ROUND(SUMIF($B$15:$B$32,"P8",$E$15:$E$32)/COUNTIFS($B$15:$B$32,"P8",$E$15:$E$32,">0"),2)) -> 4 | L15: =IF(K15="","",IF(K15<2.5,"Red",IF(K15<3.8,"Amber","Green"))) -> Green
A16: P1_Q2 | B16: P1 | C16: Governance & Control | D16: Programme reporting reflects the true status | E16: 3 | F16: =IF(E16="","",IF(E16=1,"Critical",IF(E16=2,"Weak",IF(E16=3,"At Risk",IF(E16=4,"Controlled","Strong"))))) -> At Risk | J16: Operational Readiness | K16: =IF(COUNTIFS($B$15:$B$32,"P9",$E$15:$E$32,">0")=0,"",ROUND(SUMIF($B$15:$B$32,"P9",$E$15:$E$32)/COUNTIFS($B$15:$B$32,"P9",$E$15:$E$32,">0"),2)) -> 4 | L16: =IF(K16="","",IF(K16<2.5,"Red",IF(K16<3.8,"Amber","Green"))) -> Green
A17: P2_Q1 | B17: P2 | C17: Planning & Delivery | D17: The delivery plan is realistic and credible | E17: 4 | F17: =IF(E17="","",IF(E17=1,"Critical",IF(E17=2,"Weak",IF(E17=3,"At Risk",IF(E17=4,"Controlled","Strong"))))) -> Controlled
A18: P2_Q2 | B18: P2 | C18: Planning & Delivery | D18: Risks and dependencies are actively managed | E18: 4 | F18: =IF(E18="","",IF(E18=1,"Critical",IF(E18=2,"Weak",IF(E18=3,"At Risk",IF(E18=4,"Controlled","Strong"))))) -> Controlled | J18: Indices & Flags
A19: P3_Q1 | B19: P3 | C19: Business Alignment | D19: Business objectives and KPIs are clearly defined | E19: 3 | F19: =IF(E19="","",IF(E19=1,"Critical",IF(E19=2,"Weak",IF(E19=3,"At Risk",IF(E19=4,"Controlled","Strong"))))) -> At Risk | J19: Lead Priority | K19: =IF(K5="","",IF(OR(K5<3,K8<3,K14<3,IFERROR(SEARCH("delay",$B$10),0)>0,IFERROR(SEARCH("risk",$B$10),0)>0,IFERROR(SEARCH("issue",$B$10),0)>0,IFERROR(SEARCH("problem",$B$10),0)>0,IFERROR(SEARCH("go-live",$B$10),0)>0,IFERROR(SEARCH("data",$B$10),0)>0,IFERROR(SEARCH("vendor",$B$10),0)>0),"High",IF(K5<3.8,"Medium","Low"))) -> Medium
A20: P3_Q2 | B20: P3 | C20: Business Alignment | D20: The business is actively engaged and accountable | E20: 3 | F20: =IF(E20="","",IF(E20=1,"Critical",IF(E20=2,"Weak",IF(E20=3,"At Risk",IF(E20=4,"Controlled","Strong"))))) -> At Risk
A21: P4_Q1 | B21: P4 | C21: Change & Adoption | D21: Users are prepared and involved in the programme | E21: 4 | F21: =IF(E21="","",IF(E21=1,"Critical",IF(E21=2,"Weak",IF(E21=3,"At Risk",IF(E21=4,"Controlled","Strong"))))) -> Controlled
A22: P4_Q2 | B22: P4 | C22: Change & Adoption | D22: Training and adoption readiness are on track | E22: 2 | F22: =IF(E22="","",IF(E22=1,"Critical",IF(E22=2,"Weak",IF(E22=3,"At Risk",IF(E22=4,"Controlled","Strong"))))) -> Weak
A23: P5_Q1 | B23: P5 | C23: Data Readiness | D23: Data quality and migration risks are understood | E23: 4 | F23: =IF(E23="","",IF(E23=1,"Critical",IF(E23=2,"Weak",IF(E23=3,"At Risk",IF(E23=4,"Controlled","Strong"))))) -> Controlled
A24: P5_Q2 | B24: P5 | C24: Data Readiness | D24: The business is validating data readiness | E24: 4 | F24: =IF(E24="","",IF(E24=1,"Critical",IF(E24=2,"Weak",IF(E24=3,"At Risk",IF(E24=4,"Controlled","Strong"))))) -> Controlled
A25: P6_Q1 | B25: P6 | C25: Solution & Process Fit | D25: The solution supports real business processes | E25: 4 | F25: =IF(E25="","",IF(E25=1,"Critical",IF(E25=2,"Weak",IF(E25=3,"At Risk",IF(E25=4,"Controlled","Strong"))))) -> Controlled
A26: P6_Q2 | B26: P6 | C26: Solution & Process Fit | D26: Key design decisions are validated by the business | E26: 4 | F26: =IF(E26="","",IF(E26=1,"Critical",IF(E26=2,"Weak",IF(E26=3,"At Risk",IF(E26=4,"Controlled","Strong"))))) -> Controlled
A27: P7_Q1 | B27: P7 | C27: Cutover & Go-Live | D27: Go-live planning is clear and realistic | E27: 4 | F27: =IF(E27="","",IF(E27=1,"Critical",IF(E27=2,"Weak",IF(E27=3,"At Risk",IF(E27=4,"Controlled","Strong"))))) -> Controlled
A28: P7_Q2 | B28: P7 | C28: Cutover & Go-Live | D28: Business and operational readiness for Day 1 is understood | E28: 4 | F28: =IF(E28="","",IF(E28=1,"Critical",IF(E28=2,"Weak",IF(E28=3,"At Risk",IF(E28=4,"Controlled","Strong"))))) -> Controlled
A29: P8_Q1 | B29: P8 | C29: Delivery Capability | D29: The programme team has the required capability and capacity | E29: 4 | F29: =IF(E29="","",IF(E29=1,"Critical",IF(E29=2,"Weak",IF(E29=3,"At Risk",IF(E29=4,"Controlled","Strong"))))) -> Controlled
A30: P8_Q2 | B30: P8 | C30: Delivery Capability | D30: Vendors and partners are effectively managed | E30: 4 | F30: =IF(E30="","",IF(E30=1,"Critical",IF(E30=2,"Weak",IF(E30=3,"At Risk",IF(E30=4,"Controlled","Strong"))))) -> Controlled
A31: P9_Q1 | B31: P9 | C31: Operational Readiness | D31: The support model for go-live and BAU is defined | E31: 4 | F31: =IF(E31="","",IF(E31=1,"Critical",IF(E31=2,"Weak",IF(E31=3,"At Risk",IF(E31=4,"Controlled","Strong"))))) -> Controlled
A32: P9_Q2 | B32: P9 | C32: Operational Readiness | D32: The organisation is prepared to operate the solution | E32: 4 | F32: =IF(E32="","",IF(E32=1,"Critical",IF(E32=2,"Weak",IF(E32=3,"At Risk",IF(E32=4,"Controlled","Strong"))))) -> Controlled

Sheet PHI Full
A1: Programme Health Index (Full Consultant Assessment)
A2: Consultant-led full review. Complete scores, evidence and assessor comments.
A4: Assessor Name | K4: Assessment Summary
A5: Client Company | K5: Overall Score | L5: =IF(COUNT(E17:E91)=0,"",ROUND(AVERAGE(E17:E91),2)) -> 2.96
A6: Programme Name | K6: RAG Status | L6: =IF(L5="","",IF(L5<2.5,"Red",IF(L5<3.8,"Amber","Green"))) -> Amber
A7: Programme Type | K7: Pillar Scores | L7: Score | M7: RAG
A8: Delivery Stage | K8: Governance & Decision-Making | L8: =IF(COUNTIFS($B$17:$B$91,"P1",$E$17:$E$91,">0")=0,"",ROUND(SUMIF($B$17:$B$91,"P1",$E$17:$E$91)/COUNTIFS($B$17:$B$91,"P1",$E$17:$E$91,">0"),2)) -> 3 | M8: =IF(L8="","",IF(L8<2.5,"Red",IF(L8<3.8,"Amber","Green"))) -> Amber
A9: Executive Sponsor | K9: Planning & Delivery Control | L9: =IF(COUNTIFS($B$17:$B$91,"P2",$E$17:$E$91,">0")=0,"",ROUND(SUMIF($B$17:$B$91,"P2",$E$17:$E$91)/COUNTIFS($B$17:$B$91,"P2",$E$17:$E$91,">0"),2)) -> 3 | M9: =IF(L9="","",IF(L9<2.5,"Red",IF(L9<3.8,"Amber","Green"))) -> Amber
A10: System Integrator / Vendor | K10: Business Alignment & Value | L10: =IF(COUNTIFS($B$17:$B$91,"P3",$E$17:$E$91,">0")=0,"",ROUND(SUMIF($B$17:$B$91,"P3",$E$17:$E$91)/COUNTIFS($B$17:$B$91,"P3",$E$17:$E$91,">0"),2)) -> 3 | M10: =IF(L10="","",IF(L10<2.5,"Red",IF(L10<3.8,"Amber","Green"))) -> Amber
A11: Assessment Date | K11: Change, Training & Adoption | L11: =IF(COUNTIFS($B$17:$B$91,"P4",$E$17:$E$91,">0")=0,"",ROUND(SUMIF($B$17:$B$91,"P4",$E$17:$E$91)/COUNTIFS($B$17:$B$91,"P4",$E$17:$E$91,">0"),2)) -> 3 | M11: =IF(L11="","",IF(L11<2.5,"Red",IF(L11<3.8,"Amber","Green"))) -> Amber
A12: Assessment Scope | K12: Data Readiness & Migration | L12: =IF(COUNTIFS($B$17:$B$91,"P5",$E$17:$E$91,">0")=0,"",ROUND(SUMIF($B$17:$B$91,"P5",$E$17:$E$91)/COUNTIFS($B$17:$B$91,"P5",$E$17:$E$91,">0"),2)) -> 3 | M12: =IF(L12="","",IF(L12<2.5,"Red",IF(L12<3.8,"Amber","Green"))) -> Amber
A13: Scoring guide | B13: 1 Critical | 2 Weak | 3 At Risk | 4 Controlled | 5 Strong | K13: Solution & Process Fit | L13: =IF(COUNTIFS($B$17:$B$91,"P6",$E$17:$E$91,">0")=0,"",ROUND(SUMIF($B$17:$B$91,"P6",$E$17:$E$91)/COUNTIFS($B$17:$B$91,"P6",$E$17:$E$91,">0"),2)) -> 3 | M13: =IF(L13="","",IF(L13<2.5,"Red",IF(L13<3.8,"Amber","Green"))) -> Amber
K14: Cutover & Go-Live Readiness | L14: =IF(COUNTIFS($B$17:$B$91,"P7",$E$17:$E$91,">0")=0,"",ROUND(SUMIF($B$17:$B$91,"P7",$E$17:$E$91)/COUNTIFS($B$17:$B$91,"P7",$E$17:$E$91,">0"),2)) -> 3.2 | M14: =IF(L14="","",IF(L14<2.5,"Red",IF(L14<3.8,"Amber","Green"))) -> Amber
K15: Delivery Capability & Resourcing | L15: =IF(COUNTIFS($B$17:$B$91,"P8",$E$17:$E$91,">0")=0,"",ROUND(SUMIF($B$17:$B$91,"P8",$E$17:$E$91)/COUNTIFS($B$17:$B$91,"P8",$E$17:$E$91,">0"),2)) -> 2.86 | M15: =IF(L15="","",IF(L15<2.5,"Red",IF(L15<3.8,"Amber","Green"))) -> Amber
A16: Question ID | B16: Pillar Code | C16: Pillar | D16: Question | E16: Score | F16: Status | G16: Evidence / Notes | H16: Source Type | I16: Confidence | J16: Assessor Comment | K16: Operational & Automation Readiness | L16: =IF(COUNTIFS($B$17:$B$91,"P9",$E$17:$E$91,">0")=0,"",ROUND(SUMIF($B$17:$B$91,"P9",$E$17:$E$91)/COUNTIFS($B$17:$B$91,"P9",$E$17:$E$91,">0"),2)) -> 2 | M16: =IF(L16="","",IF(L16<2.5,"Red",IF(L16<3.8,"Amber","Green"))) -> Red
A17: P1_Q1 | B17: P1 | C17: Governance & Decision-Making | D17: Decision rights are clearly defined and understood. | E17: 3 | F17: =IF(E17="","",IF(E17=1,"Critical",IF(E17=2,"Weak",IF(E17=3,"At Risk",IF(E17=4,"Controlled","Strong"))))) -> At Risk
A18: P1_Q2 | B18: P1 | C18: Governance & Decision-Making | D18: There is a functioning SteerCo with real authority. | E18: 3 | F18: =IF(E18="","",IF(E18=1,"Critical",IF(E18=2,"Weak",IF(E18=3,"At Risk",IF(E18=4,"Controlled","Strong"))))) -> At Risk | K18: Indices & Flags
A19: P1_Q3 | B19: P1 | C19: Governance & Decision-Making | D19: Escalations are timely and effective. | E19: 3 | F19: =IF(E19="","",IF(E19=1,"Critical",IF(E19=2,"Weak",IF(E19=3,"At Risk",IF(E19=4,"Controlled","Strong"))))) -> At Risk | K19: Business Readiness Index | L19: =IF(COUNT(E17:E91)=0,"",ROUND(AVERAGE(E41:E50,E58:E64,E69:E79),2)) -> 3.11
A20: P1_Q4 | B20: P1 | C20: Governance & Decision-Making | D20: Risks are openly discussed rather than filtered. | E20: 3 | F20: =IF(E20="","",IF(E20=1,"Critical",IF(E20=2,"Weak",IF(E20=3,"At Risk",IF(E20=4,"Controlled","Strong"))))) -> At Risk | K20: Value Realisation Index | L20: =IF(COUNT(E17:E91)=0,"",ROUND(AVERAGE(E31:E40),2)) -> 3
A21: P1_Q5 | B21: P1 | C21: Governance & Decision-Making | D21: Programme reporting is accurate and unmanipulated. | E21: 3 | F21: =IF(E21="","",IF(E21=1,"Critical",IF(E21=2,"Weak",IF(E21=3,"At Risk",IF(E21=4,"Controlled","Strong"))))) -> At Risk | K21: Critical Flag | L21: =IF(L5="","",IF(OR(L5<2.8,L8<2.5,L9<2.5,L12<2.5,L14<2.5),"Escalate","Monitor")) -> Monitor
A22: P1_Q6 | B22: P1 | C22: Governance & Decision-Making | D22: Roles and responsibilities are clearly defined. | E22: 3 | F22: =IF(E22="","",IF(E22=1,"Critical",IF(E22=2,"Weak",IF(E22=3,"At Risk",IF(E22=4,"Controlled","Strong"))))) -> At Risk
A23: P1_Q7 | B23: P1 | C23: Governance & Decision-Making | D23: Sponsorship is active and visible. | E23: 3 | F23: =IF(E23="","",IF(E23=1,"Critical",IF(E23=2,"Weak",IF(E23=3,"At Risk",IF(E23=4,"Controlled","Strong"))))) -> At Risk
A24: P2_Q1 | B24: P2 | C24: Planning & Delivery Control | D24: There is a credible integrated plan. | E24: 3 | F24: =IF(E24="","",IF(E24=1,"Critical",IF(E24=2,"Weak",IF(E24=3,"At Risk",IF(E24=4,"Controlled","Strong"))))) -> At Risk
A25: P2_Q2 | B25: P2 | C25: Planning & Delivery Control | D25: The critical path is clearly identified and tracked. | E25: 3 | F25: =IF(E25="","",IF(E25=1,"Critical",IF(E25=2,"Weak",IF(E25=3,"At Risk",IF(E25=4,"Controlled","Strong"))))) -> At Risk
A26: P2_Q3 | B26: P2 | C26: Planning & Delivery Control | D26: Dependencies are actively managed. | E26: 3 | F26: =IF(E26="","",IF(E26=1,"Critical",IF(E26=2,"Weak",IF(E26=3,"At Risk",IF(E26=4,"Controlled","Strong"))))) -> At Risk
A27: P2_Q4 | B27: P2 | C27: Planning & Delivery Control | D27: RAID management is effective and up to date. | E27: 3 | F27: =IF(E27="","",IF(E27=1,"Critical",IF(E27=2,"Weak",IF(E27=3,"At Risk",IF(E27=4,"Controlled","Strong"))))) -> At Risk
A28: P2_Q5 | B28: P2 | C28: Planning & Delivery Control | D28: Milestones are meaningful rather than artificial. | E28: 3 | F28: =IF(E28="","",IF(E28=1,"Critical",IF(E28=2,"Weak",IF(E28=3,"At Risk",IF(E28=4,"Controlled","Strong"))))) -> At Risk
A29: P2_Q6 | B29: P2 | C29: Planning & Delivery Control | D29: Delays are acknowledged early rather than hidden. | E29: 3 | F29: =IF(E29="","",IF(E29=1,"Critical",IF(E29=2,"Weak",IF(E29=3,"At Risk",IF(E29=4,"Controlled","Strong"))))) -> At Risk
A30: P2_Q7 | B30: P2 | C30: Planning & Delivery Control | D30: Re-planning is structured rather than reactive. | E30: 3 | F30: =IF(E30="","",IF(E30=1,"Critical",IF(E30=2,"Weak",IF(E30=3,"At Risk",IF(E30=4,"Controlled","Strong"))))) -> At Risk
A31: P3_Q1 | B31: P3 | C31: Business Alignment & Value | D31: Business KPIs are clearly defined. | E31: 3 | F31: =IF(E31="","",IF(E31=1,"Critical",IF(E31=2,"Weak",IF(E31=3,"At Risk",IF(E31=4,"Controlled","Strong"))))) -> At Risk
A32: P3_Q2 | B32: P3 | C32: Business Alignment & Value | D32: A measurable baseline exists. | E32: 3 | F32: =IF(E32="","",IF(E32=1,"Critical",IF(E32=2,"Weak",IF(E32=3,"At Risk",IF(E32=4,"Controlled","Strong"))))) -> At Risk
A33: P3_Q3 | B33: P3 | C33: Business Alignment & Value | D33: Benefits are measurable. | E33: 3 | F33: =IF(E33="","",IF(E33=1,"Critical",IF(E33=2,"Weak",IF(E33=3,"At Risk",IF(E33=4,"Controlled","Strong"))))) -> At Risk
... A68: P7_Q4 | B68: P7 | C68: Cutover & Go-Live Readiness | D68: Data sign-offs are defined. | E68: 3 | F68: =IF(E68="","",IF(E68=1,"Critical",IF(E68=2,"Weak",IF(E68=3,"At Risk",IF(E68=4,"Controlled","Strong"))))) -> At Risk
A69: P7_Q5 | B69: P7 | C69: Cutover & Go-Live Readiness | D69: Day 1 business processes are defined. | E69: 3 | F69: =IF(E69="","",IF(E69=1,"Critical",IF(E69=2,"Weak",IF(E69=3,"At Risk",IF(E69=4,"Controlled","Strong"))))) -> At Risk | H69: observation
A70: P7_Q6 | B70: P7 | C70: Cutover & Go-Live Readiness | D70: Roles and responsibilities are clear. | E70: 3 | F70: =IF(E70="","",IF(E70=1,"Critical",IF(E70=2,"Weak",IF(E70=3,"At Risk",IF(E70=4,"Controlled","Strong"))))) -> At Risk
A71: P7_Q7 | B71: P7 | C71: Cutover & Go-Live Readiness | D71: Manual processes are identified. | E71: 3 | F71: =IF(E71="","",IF(E71=1,"Critical",IF(E71=2,"Weak",IF(E71=3,"At Risk",IF(E71=4,"Controlled","Strong"))))) -> At Risk
A72: P7_Q8 | B72: P7 | C72: Cutover & Go-Live Readiness | D72: Dependencies are mapped. | E72: 3 | F72: =IF(E72="","",IF(E72=1,"Critical",IF(E72=2,"Weak",IF(E72=3,"At Risk",IF(E72=4,"Controlled","Strong"))))) -> At Risk
A73: P7_Q9 | B73: P7 | C73: Cutover & Go-Live Readiness | D73: A detailed cutover runbook exists. | E73: 3 | F73: =IF(E73="","",IF(E73=1,"Critical",IF(E73=2,"Weak",IF(E73=3,"At Risk",IF(E73=4,"Controlled","Strong"))))) -> At Risk
A74: P7_Q10 | B74: P7 | C74: Cutover & Go-Live Readiness | D74: Timeline is defined at practical level. | E74: 3 | F74: =IF(E74="","",IF(E74=1,"Critical",IF(E74=2,"Weak",IF(E74=3,"At Risk",IF(E74=4,"Controlled","Strong"))))) -> At Risk
A75: P7_Q11 | B75: P7 | C75: Cutover & Go-Live Readiness | D75: Rehearsals have been completed. | E75: 3 | F75: =IF(E75="","",IF(E75=1,"Critical",IF(E75=2,"Weak",IF(E75=3,"At Risk",IF(E75=4,"Controlled","Strong"))))) -> At Risk
...

Sheet ITSM Snapshot
A1: Service Health Check (ITSM-HI Snapshot)
A2: Public-facing service diagnostic. Use only blue cells for input.
A4: Client / Assessor Name | J4: Assessment Summary
A5: Job Title | J5: Overall Score | K5: =IF(COUNT(E15:E36)=0,"",ROUND(AVERAGE(E15:E36),2))
A6: Company | J6: RAG Status | K6: =IF(K5="","",IF(K5<2.5,"Red",IF(K5<3.8,"Amber","Green")))
A7: Service / Platform Name | J7: Pillar Scores | K7: Score | L7: RAG
A8: Service Scope | J8: Service Governance & Ownership | K8: =IF(COUNTIFS($B$15:$B$36,"P1",$E$15:$E$36,">0")=0,"",ROUND(SUMIF($B$15:$B$36,"P1",$E$15:$E$36)/COUNTIFS($B$15:$B$36,"P1",$E$15:$E$36,">0"),2)) | L8: =IF(K8="","",IF(K8<2.5,"Red",IF(K8<3.8,"Amber","Green")))
A9: Support Model | J9: Incident & Major Incident Management | K9: =IF(COUNTIFS($B$15:$B$36,"P2",$E$15:$E$36,">0")=0,"",ROUND(SUMIF($B$15:$B$36,"P2",$E$15:$E$36)/COUNTIFS($B$15:$B$36,"P2",$E$15:$E$36,">0"),2)) | L9: =IF(K9="","",IF(K9<2.5,"Red",IF(K9<3.8,"Amber","Green")))
A10: Primary Concern | J10: Service Request Management | K10: =IF(COUNTIFS($B$15:$B$36,"P3",$E$15:$E$36,">0")=0,"",ROUND(SUMIF($B$15:$B$36,"P3",$E$15:$E$36)/COUNTIFS($B$15:$B$36,"P3",$E$15:$E$36,">0"),2)) | L10: =IF(K10="","",IF(K10<2.5,"Red",IF(K10<3.8,"Amber","Green")))
A11: Scoring guide | B11: 1 Critical | 2 Weak | 3 At Risk | 4 Controlled | 5 Strong | J11: Problem Management | K11: =IF(COUNTIFS($B$15:$B$36,"P4",$E$15:$E$36,">0")=0,"",ROUND(SUMIF($B$15:$B$36,"P4",$E$15:$E$36)/COUNTIFS($B$15:$B$36,"P4",$E$15:$E$36,">0"),2)) | L11: =IF(K11="","",IF(K11<2.5,"Red",IF(K11<3.8,"Amber","Green")))
J12: Change & Release Management | K12: =IF(COUNTIFS($B$15:$B$36,"P5",$E$15:$E$36,">0")=0,"",ROUND(SUMIF($B$15:$B$36,"P5",$E$15:$E$36)/COUNTIFS($B$15:$B$36,"P5",$E$15:$E$36,">0"),2)) | L12: =IF(K12="","",IF(K12<2.5,"Red",IF(K12<3.8,"Amber","Green")))
J13: Service Performance, SLA & Reporting | K13: =IF(COUNTIFS($B$15:$B$36,"P6",$E$15:$E$36,">0")=0,"",ROUND(SUMIF($B$15:$B$36,"P6",$E$15:$E$36)/COUNTIFS($B$15:$B$36,"P6",$E$15:$E$36,">0"),2)) | L13: =IF(K13="","",IF(K13<2.5,"Red",IF(K13<3.8,"Amber","Green")))
A14: Question ID | B14: Pillar Code | C14: Pillar | D14: Question | E14: Score | F14: Status | G14: Notes / Context | J14: Service Transition & BAU Readiness | K14: =IF(COUNTIFS($B$15:$B$36,"P7",$E$15:$E$36,">0")=0,"",ROUND(SUMIF($B$15:$B$36,"P7",$E$15:$E$36)/COUNTIFS($B$15:$B$36,"P7",$E$15:$E$36,">0"),2)) | L14: =IF(K14="","",IF(K14<2.5,"Red",IF(K14<3.8,"Amber","Green")))
A15: P1_Q1 | B15: P1 | C15: Service Governance & Ownership | D15: Service ownership and accountability are clearly defined. | F15: =IF(E15="","",IF(E15=1,"Critical",IF(E15=2,"Weak",IF(E15=3,"At Risk",IF(E15=4,"Controlled","Strong"))))) | J15: Service Operations & Support Model | K15: =IF(COUNTIFS($B$15:$B$36,"P8",$E$15:$E$36,">0")=0,"",ROUND(SUMIF($B$15:$B$36,"P8",$E$15:$E$36)/COUNTIFS($B$15:$B$36,"P8",$E$15:$E$36,">0"),2)) | L15: =IF(K15="","",IF(K15<2.5,"Red",IF(K15<3.8,"Amber","Green")))
A16: P1_Q2 | B16: P1 | C16: Service Governance & Ownership | D16: Service governance and performance review are active and effective. | F16: =IF(E16="","",IF(E16=1,"Critical",IF(E16=2,"Weak",IF(E16=3,"At Risk",IF(E16=4,"Controlled","Strong"))))) | J16: Supplier & Vendor Service Management | K16: =IF(COUNTIFS($B$15:$B$36,"P9",$E$15:$E$36,">0")=0,"",ROUND(SUMIF($B$15:$B$36,"P9",$E$15:$E$36)/COUNTIFS($B$15:$B$36,"P9",$E$15:$E$36,">0"),2)) | L16: =IF(K16="","",IF(K16<2.5,"Red",IF(K16<3.8,"Amber","Green")))
A17: P2_Q1 | B17: P2 | C17: Incident & Major Incident Management | D17: Incidents are resolved in a controlled and timely manner. | F17: =IF(E17="","",IF(E17=1,"Critical",IF(E17=2,"Weak",IF(E17=3,"At Risk",IF(E17=4,"Controlled","Strong"))))) | J17: Operational Resilience & Continuity | K17: =IF(COUNTIFS($B$15:$B$36,"P10",$E$15:$E$36,">0")=0,"",ROUND(SUMIF($B$15:$B$36,"P10",$E$15:$E$36)/COUNTIFS($B$15:$B$36,"P10",$E$15:$E$36,">0"),2)) | L17: =IF(K17="","",IF(K17<2.5,"Red",IF(K17<3.8,"Amber","Green")))
A18: P2_Q2 | B18: P2 | C18: Incident & Major Incident Management | D18: Major incidents are handled with clear escalation and communication. | F18: =IF(E18="","",IF(E18=1,"Critical",IF(E18=2,"Weak",IF(E18=3,"At Risk",IF(E18=4,"Controlled","Strong"))))) | J18: Automation, Tooling & Service Optimisation | K18: =IF(COUNTIFS($B$15:$B$36,"P11",$E$15:$E$36,">0")=0,"",ROUND(SUMIF($B$15:$B$36,"P11",$E$15:$E$36)/COUNTIFS($B$15:$B$36,"P11",$E$15:$E$36,">0"),2)) | L18: =IF(K18="","",IF(K18<2.5,"Red",IF(K18<3.8,"Amber","Green")))
A19: P3_Q1 | B19: P3 | C19: Service Request Management | D19: Service requests are standardised and clearly separated from incidents. | F19: =IF(E19="","",IF(E19=1,"Critical",IF(E19=2,"Weak",IF(E19=3,"At Risk",IF(E19=4,"Controlled","Strong")))))
A20: P3_Q2 | B20: P3 | C20: Service Request Management | D20: Requests are fulfilled efficiently and within expected timescales. | F20: =IF(E20="","",IF(E20=1,"Critical",IF(E20=2,"Weak",IF(E20=3,"At Risk",IF(E20=4,"Controlled","Strong"))))) | J20: Indices & Flags
A21: P4_Q1 | B21: P4 | C21: Problem Management | D21: Recurring issues are investigated and root causes addressed. | F21: =IF(E21="","",IF(E21=1,"Critical",IF(E21=2,"Weak",IF(E21=3,"At Risk",IF(E21=4,"Controlled","Strong"))))) | J21: Service Stability Index | K21: =IF(COUNT(E15:E36)=0,"",ROUND(AVERAGE(E17:E24),2))
A22: P4_Q2 | B22: P4 | C22: Problem Management | D22: Problem management reduces repeat incidents over time. | F22: =IF(E22="","",IF(E22=1,"Critical",IF(E22=2,"Weak",IF(E22=3,"At Risk",IF(E22=4,"Controlled","Strong"))))) | J22: Service Maturity Index | K22: =IF(COUNT(E15:E36)=0,"",ROUND(AVERAGE(E15:E16,E25:E26,E35:E36),2))
A23: P5_Q1 | B23: P5 | C23: Change & Release Management | D23: Changes are controlled and do not regularly create instability. | F23: =IF(E23="","",IF(E23=1,"Critical",IF(E23=2,"Weak",IF(E23=3,"At Risk",IF(E23=4,"Controlled","Strong"))))) | J23: BAU Readiness Index | K23: =IF(COUNT(E15:E36)=0,"",ROUND(AVERAGE(E27:E30),2))
A24: P5_Q2 | B24: P5 | C24: Change & Release Management | D24: Releases are planned, tested, and deployed in a structured way. | F24: =IF(E24="","",IF(E24=1,"Critical",IF(E24=2,"Weak",IF(E24=3,"At Risk",IF(E24=4,"Controlled","Strong"))))) | J24: Lead Priority | K24: =IF(K5="","",IF(OR(K5<3,K9<3,K12<3,K14<3,K17<3,IFERROR(SEARCH("outage",$B$10),0)>0,IFERROR(SEARCH("instability",$B$10),0)>0,IFERROR(SEARCH("backlog",$B$10),0)>0,IFERROR(SEARCH("vendor",$B$10),0)>0,IFERROR(SEARCH("sla",$B$10),0)>0),"High",IF(K5<3.8,"Medium","Low")))
A25: P6_Q1 | B25: P6 | C25: Service Performance, SLA & Reporting | D25: SLAs and KPIs reflect real service performance. | F25: =IF(E25="","",IF(E25=1,"Critical",IF(E25=2,"Weak",IF(E25=3,"At Risk",IF(E25=4,"Controlled","Strong")))))
A26: P6_Q2 | B26: P6 | C26: Service Performance, SLA & Reporting | D26: Reporting is trusted and used to drive improvement. | F26: =IF(E26="","",IF(E26=1,"Critical",IF(E26=2,"Weak",IF(E26=3,"At Risk",IF(E26=4,"Controlled","Strong")))))
A27: P7_Q1 | B27: P7 | C27: Service Transition & BAU Readiness | D27: New or changed services are handed over to BAU in a structured way. | F27: =IF(E27="","",IF(E27=1,"Critical",IF(E27=2,"Weak",IF(E27=3,"At Risk",IF(E27=4,"Controlled","Strong")))))
A28: P7_Q2 | B28: P7 | C28: Service Transition & BAU Readiness | D28: Documentation, training, and knowledge transfer support live operations. | F28: =IF(E28="","",IF(E28=1,"Critical",IF(E28=2,"Weak",IF(E28=3,"At Risk",IF(E28=4,"Controlled","Strong")))))
A29: P8_Q1 | B29: P8 | C29: Service Operations & Support Model | D29: The support model is clear and effective in practice. | F29: =IF(E29="","",IF(E29=1,"Critical",IF(E29=2,"Weak",IF(E29=3,"At Risk",IF(E29=4,"Controlled","Strong")))))
A30: P8_Q2 | B30: P8 | C30: Service Operations & Support Model | D30: Ticket ownership, escalation, and backlog control are working. | F30: =IF(E30="","",IF(E30=1,"Critical",IF(E30=2,"Weak",IF(E30=3,"At Risk",IF(E30=4,"Controlled","Strong")))))
A31: P9_Q1 | B31: P9 | C31: Supplier & Vendor Service Management | D31: Vendors are accountable for service performance. | F31: =IF(E31="","",IF(E31=1,"Critical",IF(E31=2,"Weak",IF(E31=3,"At Risk",IF(E31=4,"Controlled","Strong")))))
A32: P9_Q2 | B32: P9 | C32: Supplier & Vendor Service Management | D32: Internal and external teams work in a coordinated way. | F32: =IF(E32="","",IF(E32=1,"Critical",IF(E32=2,"Weak",IF(E32=3,"At Risk",IF(E32=4,"Controlled","Strong")))))
A33: P10_Q1 | B33: P10 | C33: Operational Resilience & Continuity | D33: Disaster recovery, backup, and continuity controls are reliable. | F33: =IF(E33="","",IF(E33=1,"Critical",IF(E33=2,"Weak",IF(E33=3,"At Risk",IF(E33=4,"Controlled","Strong")))))
A34: P10_Q2 | B34: P10 | C34: Operational Resilience & Continuity | D34: Critical service failure scenarios are understood and planned for. | F34: =IF(E34="","",IF(E34=1,"Critical",IF(E34=2,"Weak",IF(E34=3,"At Risk",IF(E34=4,"Controlled","Strong")))))
A35: P11_Q1 | B35: P11 | C35: Automation, Tooling & Service Optimisation | D35: Service processes are supported by effective tools and automation. | F35: =IF(E35="","",IF(E35=1,"Critical",IF(E35=2,"Weak",IF(E35=3,"At Risk",IF(E35=4,"Controlled","Strong")))))
A36: P11_Q2 | B36: P11 | C36: Automation, Tooling & Service Optimisation | D36: Self-service, knowledge management, or workflow optimisation is in place. | F36: =IF(E36="","",IF(E36=1,"Critical",IF(E36=2,"Weak",IF(E36=3,"At Risk",IF(E36=4,"Controlled","Strong")))))

Sheet ITSM Full
A1: ITSM Health Index (Full Consultant Assessment)
A2: Consultant-led service health and operational maturity review.
A4: Assessor Name | K4: Assessment Summary
A5: Client Company | K5: Overall Score | L5: =IF(COUNT(E17:E81)=0,"",ROUND(AVERAGE(E17:E81),2))
A6: Service Name | K6: RAG Status | L6: =IF(L5="","",IF(L5<2.5,"Red",IF(L5<3.8,"Amber","Green")))
A7: Service Scope | K7: Pillar Scores | L7: Score | M7: RAG
A8: Service Criticality | K8: Service Governance & Ownership | L8: =IF(COUNTIFS($B$17:$B$81,"P1",$E$17:$E$81,">0")=0,"",ROUND(SUMIF($B$17:$B$81,"P1",$E$17:$E$81)/COUNTIFS($B$17:$B$81,"P1",$E$17:$E$81,">0"),2)) | M8: =IF(L8="","",IF(L8<2.5,"Red",IF(L8<3.8,"Amber","Green")))
A9: Support Model | K9: Incident & Major Incident Management | L9: =IF(COUNTIFS($B$17:$B$81,"P2",$E$17:$E$81,">0")=0,"",ROUND(SUMIF($B$17:$B$81,"P2",$E$17:$E$81)/COUNTIFS($B$17:$B$81,"P2",$E$17:$E$81,">0"),2)) | M9: =IF(L9="","",IF(L9<2.5,"Red",IF(L9<3.8,"Amber","Green")))
A10: Service Hours | K10: Service Request Management | L10: =IF(COUNTIFS($B$17:$B$81,"P3",$E$17:$E$81,">0")=0,"",ROUND(SUMIF($B$17:$B$81,"P3",$E$17:$E$81)/COUNTIFS($B$17:$B$81,"P3",$E$17:$E$81,">0"),2)) | M10: =IF(L10="","",IF(L10<2.5,"Red",IF(L10<3.8,"Amber","Green")))
A11: Assessment Date | K11: Problem Management | L11: =IF(COUNTIFS($B$17:$B$81,"P4",$E$17:$E$81,">0")=0,"",ROUND(SUMIF($B$17:$B$81,"P4",$E$17:$E$81)/COUNTIFS($B$17:$B$81,"P4",$E$17:$E$81,">0"),2)) | M11: =IF(L11="","",IF(L11<2.5,"Red",IF(L11<3.8,"Amber","Green")))
A12: Assessment Scope | K12: Change & Release Management | L12: =IF(COUNTIFS($B$17:$B$81,"P5",$E$17:$E$81,">0")=0,"",ROUND(SUMIF($B$17:$B$81,"P5",$E$17:$E$81)/COUNTIFS($B$17:$B$81,"P5",$E$17:$E$81,">0"),2)) | M12: =IF(L12="","",IF(L12<2.5,"Red",IF(L12<3.8,"Amber","Green")))
A13: Scoring guide | B13: 1 Critical | 2 Weak | 3 At Risk | 4 Controlled | 5 Strong | K13: Service Performance, SLA & Reporting | L13: =IF(COUNTIFS($B$17:$B$81,"P6",$E$17:$E$81,">0")=0,"",ROUND(SUMIF($B$17:$B$81,"P6",$E$17:$E$81)/COUNTIFS($B$17:$B$81,"P6",$E$17:$E$81,">0"),2)) | M13: =IF(L13="","",IF(L13<2.5,"Red",IF(L13<3.8,"Amber","Green")))
K14: Service Transition & BAU Readiness | L14: =IF(COUNTIFS($B$17:$B$81,"P7",$E$17:$E$81,">0")=0,"",ROUND(SUMIF($B$17:$B$81,"P7",$E$17:$E$81)/COUNTIFS($B$17:$B$81,"P7",$E$17:$E$81,">0"),2)) | M14: =IF(L14="","",IF(L14<2.5,"Red",IF(L14<3.8,"Amber","Green")))
K15: Service Operations & Support Model | L15: =IF(COUNTIFS($B$17:$B$81,"P8",$E$17:$E$81,">0")=0,"",ROUND(SUMIF($B$17:$B$81,"P8",$E$17:$E$81)/COUNTIFS($B$17:$B$81,"P8",$E$17:$E$81,">0"),2)) | M15: =IF(L15="","",IF(L15<2.5,"Red",IF(L15<3.8,"Amber","Green")))
A16: Question ID | B16: Pillar Code | C16: Pillar | D16: Question | E16: Score | F16: Status | G16: Evidence / Notes | H16: Source Type | I16: Confidence | J16: Assessor Comment | K16: Supplier & Vendor Service Management | L16: =IF(COUNTIFS($B$17:$B$81,"P9",$E$17:$E$81,">0")=0,"",ROUND(SUMIF($B$17:$B$81,"P9",$E$17:$E$81)/COUNTIFS($B$17:$B$81,"P9",$E$17:$E$81,">0"),2)) | M16: =IF(L16="","",IF(L16<2.5,"Red",IF(L16<3.8,"Amber","Green")))
A17: P1_Q1 | B17: P1 | C17: Service Governance & Ownership | D17: Service ownership is clearly defined across business and IT. | F17: =IF(E17="","",IF(E17=1,"Critical",IF(E17=2,"Weak",IF(E17=3,"At Risk",IF(E17=4,"Controlled","Strong"))))) | K17: Operational Resilience & Continuity | L17: =IF(COUNTIFS($B$17:$B$81,"P10",$E$17:$E$81,">0")=0,"",ROUND(SUMIF($B$17:$B$81,"P10",$E$17:$E$81)/COUNTIFS($B$17:$B$81,"P10",$E$17:$E$81,">0"),2)) | M17: =IF(L17="","",IF(L17<2.5,"Red",IF(L17<3.8,"Amber","Green")))
A18: P1_Q2 | B18: P1 | C18: Service Governance & Ownership | D18: The service catalogue exists and is maintained. | F18: =IF(E18="","",IF(E18=1,"Critical",IF(E18=2,"Weak",IF(E18=3,"At Risk",IF(E18=4,"Controlled","Strong"))))) | K18: Automation, Tooling & Service Optimisation | L18: =IF(COUNTIFS($B$17:$B$81,"P11",$E$17:$E$81,">0")=0,"",ROUND(SUMIF($B$17:$B$81,"P11",$E$17:$E$81)/COUNTIFS($B$17:$B$81,"P11",$E$17:$E$81,">0"),2)) | M18: =IF(L18="","",IF(L18<2.5,"Red",IF(L18<3.8,"Amber","Green")))
A19: P1_Q3 | B19: P1 | C19: Service Governance & Ownership | D19: Governance forums for service performance are active and effective. | F19: =IF(E19="","",IF(E19=1,"Critical",IF(E19=2,"Weak",IF(E19=3,"At Risk",IF(E19=4,"Controlled","Strong")))))
A20: P1_Q4 | B20: P1 | C20: Service Governance & Ownership | D20: SLA and KPI ownership is clearly assigned. | F20: =IF(E20="","",IF(E20=1,"Critical",IF(E20=2,"Weak",IF(E20=3,"At Risk",IF(E20=4,"Controlled","Strong"))))) | K20: Indices & Flags
A21: P1_Q5 | B21: P1 | C21: Service Governance & Ownership | D21: Decision-making and escalation paths are structured. | F21: =IF(E21="","",IF(E21=1,"Critical",IF(E21=2,"Weak",IF(E21=3,"At Risk",IF(E21=4,"Controlled","Strong"))))) | K21: Service Stability Index | L21: =IF(COUNT(E17:E81)=0,"",ROUND(AVERAGE(E22:E27,E34:E39,E40:E45),2))
A22: P2_Q1 | B22: P2 | C22: Incident & Major Incident Management | D22: Incident management is defined and consistently followed. | F22: =IF(E22="","",IF(E22=1,"Critical",IF(E22=2,"Weak",IF(E22=3,"At Risk",IF(E22=4,"Controlled","Strong"))))) | K22: Service Maturity Index | L22: =IF(COUNT(E17:E81)=0,"",ROUND(AVERAGE(E17:E21,E46:E51,E76:E81),2))
A23: P2_Q2 | B23: P2 | C23: Incident & Major Incident Management | D23: MTTR is tracked and actively improved. | F23: =IF(E23="","",IF(E23=1,"Critical",IF(E23=2,"Weak",IF(E23=3,"At Risk",IF(E23=4,"Controlled","Strong"))))) | K23: BAU Readiness Index | L23: =IF(COUNT(E17:E81)=0,"",ROUND(AVERAGE(E52:E57,E58:E63),2))
A24: P2_Q3 | B24: P2 | C24: Incident & Major Incident Management | D24: Major incident handling is structured and controlled. | F24: =IF(E24="","",IF(E24=1,"Critical",IF(E24=2,"Weak",IF(E24=3,"At Risk",IF(E24=4,"Controlled","Strong"))))) | K24: Critical Flag | L24: =IF(L5="","",IF(OR(L5<2.8,L9<2.5,L12<2.5,L14<2.5,L17<2.5),"Escalate","Monitor"))
A25: P2_Q4 | B25: P2 | C25: Incident & Major Incident Management | D25: Escalation paths are clear and respected. | F25: =IF(E25="","",IF(E25=1,"Critical",IF(E25=2,"Weak",IF(E25=3,"At Risk",IF(E25=4,"Controlled","Strong")))))
A26: P2_Q5 | B26: P2 | C26: Incident & Major Incident Management | D26: Incident communication is timely and effective. | F26: =IF(E26="","",IF(E26=1,"Critical",IF(E26=2,"Weak",IF(E26=3,"At Risk",IF(E26=4,"Controlled","Strong")))))
A27: P2_Q6 | B27: P2 | C27: Incident & Major Incident Management | D27: Incident trends are analysed. | F27: =IF(E27="","",IF(E27=1,"Critical",IF(E27=2,"Weak",IF(E27=3,"At Risk",IF(E27=4,"Controlled","Strong")))))
A28: P3_Q1 | B28: P3 | C28: Service Request Management | D28: The service request catalogue is defined and maintained. | F28: =IF(E28="","",IF(E28=1,"Critical",IF(E28=2,"Weak",IF(E28=3,"At Risk",IF(E28=4,"Controlled","Strong")))))
A29: P3_Q2 | B29: P3 | C29: Service Request Management | D29: Requests are clearly separated from incidents. | F29: =IF(E29="","",IF(E29=1,"Critical",IF(E29=2,"Weak",IF(E29=3,"At Risk",IF(E29=4,"Controlled","Strong")))))
A30: P3_Q3 | B30: P3 | C30: Service Request Management | D30: Standard requests are documented and repeatable. | F30: =IF(E30="","",IF(E30=1,"Critical",IF(E30=2,"Weak",IF(E30=3,"At Risk",IF(E30=4,"Controlled","Strong")))))
A31: P3_Q4 | B31: P3 | C31: Service Request Management | D31: Request fulfilment times are defined and tracked. | F31: =IF(E31="","",IF(E31=1,"Critical",IF(E31=2,"Weak",IF(E31=3,"At Risk",IF(E31=4,"Controlled","Strong")))))
A32: P3_Q5 | B32: P3 | C32: Service Request Management | D32: Self-service capability exists where appropriate. | F32: =IF(E32="","",IF(E32=1,"Critical",IF(E32=2,"Weak",IF(E32=3,"At Risk",IF(E32=4,"Controlled","Strong")))))
A33: P3_Q6 | B33: P3 | C33: Service Request Management | D33: Request fulfilment is automated where possible. | F33: =IF(E33="","",IF(E33=1,"Critical",IF(E33=2,"Weak",IF(E33=3,"At Risk",IF(E33=4,"Controlled","Strong")))))
A34: P4_Q1 | B34: P4 | C34: Problem Management | D34: Problems are formally logged and prioritised. | F34: =IF(E34="","",IF(E34=1,"Critical",IF(E34=2,"Weak",IF(E34=3,"At Risk",IF(E34=4,"Controlled","Strong")))))
A35: P4_Q2 | B35: P4 | C35: Problem Management | D35: Root Cause Analysis is performed effectively. | F35: =IF(E35="","",IF(E35=1,"Critical",IF(E35=2,"Weak",IF(E35=3,"At Risk",IF(E35=4,"Controlled","Strong")))))
A36: P4_Q3 | B36: P4 | C36: Problem Management | D36: A Known Error Database is maintained where appropriate. | F36: =IF(E36="","",IF(E36=1,"Critical",IF(E36=2,"Weak",IF(E36=3,"At Risk",IF(E36=4,"Controlled","Strong")))))
... A81: P11_Q6 | B81: P11 | C81: Automation, Tooling & Service Optimisation | D81: AI or predictive capability is considered where relevant. | F81: =IF(E81="","",IF(E81=1,"Critical",IF(E81=2,"Weak",IF(E81=3,"At Risk",IF(E81=4,"Controlled","Strong")))))

Sheet PHI Snapshot Dash
A1: PHI Snapshot Dashboard
A2: Use after completing the Programme Health Check input sheet.
A4: Overall Score | C4: RAG Status | E4: Lead Priority
A5: ='PHI Snapshot'!K5 -> 3.67 | C5: ='PHI Snapshot'!K6 -> Amber | E5: ='PHI Snapshot'!K19 -> Medium
A11: Pillar | B11: Score | C11: RAG
A12: Governance & Control | B12: ='PHI Snapshot'!K8 -> 3 | C12: ='PHI Snapshot'!L8 -> Amber
A13: Planning & Delivery | B13: ='PHI Snapshot'!K9 -> 4 | C13: ='PHI Snapshot'!L9 -> Green
A14: Business Alignment | B14: ='PHI Snapshot'!K10 -> 3 | C14: ='PHI Snapshot'!L10 -> Amber
A15: Change & Adoption | B15: ='PHI Snapshot'!K11 -> 3 | C15: ='PHI Snapshot'!L11 -> Amber
A16: Data Readiness | B16: ='PHI Snapshot'!K12 -> 4 | C16: ='PHI Snapshot'!L12 -> Green
A17: Solution & Process Fit | B17: ='PHI Snapshot'!K13 -> 4 | C17: ='PHI Snapshot'!L13 -> Green
A18: Cutover & Go-Live | B18: ='PHI Snapshot'!K14 -> 4 | C18: ='PHI Snapshot'!L14 -> Green
A19: Delivery Capability | B19: ='PHI Snapshot'!K15 -> 4 | C19: ='PHI Snapshot'!L15 -> Green
A20: Operational Readiness | B20: ='PHI Snapshot'!K16 -> 4 | C20: ='PHI Snapshot'!L16 -> Green

Sheet PHI Full Dash
A1: PHI Full Dashboard
A2: Consultant view of the full Programme Health Index assessment.
A4: Overall Score | C4: RAG Status | E4: Business Readiness Index | G4: Value Realisation Index
A5: ='PHI Full'!L5 -> 2.96 | C5: ='PHI Full'!L6 -> Amber | E5: ='PHI Full'!L19 -> 3.11 | G5: ='PHI Full'!L20 -> 3
A7: Critical Flag
A8: ='PHI Full'!L21 -> Monitor
A11: Pillar | B11: Score | C11: RAG
A12: Governance & Decision-Making | B12: ='PHI Full'!L8 -> 3 | C12: ='PHI Full'!M8 -> Amber
A13: Planning & Delivery Control | B13: ='PHI Full'!L9 -> 3 | C13: ='PHI Full'!M9 -> Amber
A14: Business Alignment & Value | B14: ='PHI Full'!L10 -> 3 | C14: ='PHI Full'!M10 -> Amber
A15: Change, Training & Adoption | B15: ='PHI Full'!L11 -> 3 | C15: ='PHI Full'!M11 -> Amber
A16: Data Readiness & Migration | B16: ='PHI Full'!L12 -> 3 | C16: ='PHI Full'!M12 -> Amber
A17: Solution & Process Fit | B17: ='PHI Full'!L13 -> 3 | C17: ='PHI Full'!M13 -> Amber
A18: Cutover & Go-Live Readiness | B18: ='PHI Full'!L14 -> 3.2 | C18: ='PHI Full'!M14 -> Amber
A19: Delivery Capability & Resourcing | B19: ='PHI Full'!L15 -> 2.86 | C19: ='PHI Full'!M15 -> Amber
A20: Operational & Automation Readiness | B20: ='PHI Full'!L16 -> 2 | C20: ='PHI Full'!M16 -> Red

Sheet ITSM Snapshot Dash
A1: ITSM Snapshot Dashboard
A2: Use after completing the Service Health Check input sheet.
A4: Overall Score | C4: RAG Status | E4: Service Stability Index | G4: Service Maturity Index
A5: ='ITSM Snapshot'!K5 | C5: ='ITSM Snapshot'!K6 | E5: ='ITSM Snapshot'!K21 | G5: ='ITSM Snapshot'!K22
A7: BAU Readiness Index | C7: Lead Priority
A8: ='ITSM Snapshot'!K23 | C8: ='ITSM Snapshot'!K24
A11: Pillar | B11: Score | C11: RAG
A12: Service Governance & Ownership | B12: ='ITSM Snapshot'!K8 | C12: ='ITSM Snapshot'!L8
A13: Incident & Major Incident Management | B13: ='ITSM Snapshot'!K9 | C13: ='ITSM Snapshot'!L9
A14: Service Request Management | B14: ='ITSM Snapshot'!K10 | C14: ='ITSM Snapshot'!L10
A15: Problem Management | B15: ='ITSM Snapshot'!K11 | C15: ='ITSM Snapshot'!L11
A16: Change & Release Management | B16: ='ITSM Snapshot'!K12 | C16: ='ITSM Snapshot'!L12
A17: Service Performance, SLA & Reporting | B17: ='ITSM Snapshot'!K13 | C17: ='ITSM Snapshot'!L13
A18: Service Transition & BAU Readiness | B18: ='ITSM Snapshot'!K14 | C18: ='ITSM Snapshot'!L14
A19: Service Operations & Support Model | B19: ='ITSM Snapshot'!K15 | C19: ='ITSM Snapshot'!L15
A20: Supplier & Vendor Service Management | B20: ='ITSM Snapshot'!K16 | C20: ='ITSM Snapshot'!L16
A21: Operational Resilience & Continuity | B21: ='ITSM Snapshot'!K17 | C21: ='ITSM Snapshot'!L17
A22: Automation, Tooling & Service Optimisation | B22: ='ITSM Snapshot'!K18 | C22: ='ITSM Snapshot'!L18

Sheet ITSM Full Dash
A1: ITSM Full Dashboard
A2: Consultant view of the full ITSM Health Index assessment.
A4: Overall Score | C4: RAG Status | E4: Service Stability Index | G4: Service Maturity Index
A5: ='ITSM Full'!L5 | C5: ='ITSM Full'!L6 | E5: ='ITSM Full'!L21 | G5: ='ITSM Full'!L22
A7: BAU Readiness Index | C7: Critical Flag
A8: ='ITSM Full'!L23 | C8: ='ITSM Full'!L24
A11: Pillar | B11: Score | C11: RAG
A12: Service Governance & Ownership | B12: ='ITSM Full'!L8 | C12: ='ITSM Full'!M8
A13: Incident & Major Incident Management | B13: ='ITSM Full'!L9 | C13: ='ITSM Full'!M9
A14: Service Request Management | B14: ='ITSM Full'!L10 | C14: ='ITSM Full'!M10
A15: Problem Management | B15: ='ITSM Full'!L11 | C15: ='ITSM Full'!M11
A16: Change & Release Management | B16: ='ITSM Full'!L12 | C16: ='ITSM Full'!M12
A17: Service Performance, SLA & Reporting | B17: ='ITSM Full'!L13 | C17: ='ITSM Full'!M13
A18: Service Transition & BAU Readiness | B18: ='ITSM Full'!L14 | C18: ='ITSM Full'!M14
A19: Service Operations & Support Model | B19: ='ITSM Full'!L15 | C19: ='ITSM Full'!M15
A20: Supplier & Vendor Service Management | B20: ='ITSM Full'!L16 | C20: ='ITSM Full'!M16
A21: Operational Resilience & Continuity | B21: ='ITSM Full'!L17 | C21: ='ITSM Full'!M17
A22: Automation, Tooling & Service Optimisation | B22: ='ITSM Full'!L18 | C22: ='ITSM Full'!M18

Sheet AI - PHI
A1: AI Prompt Builder - PHI
A2: Copy the prompt below and pair it with the relevant dashboard scores and evidence notes from the input sheet.
A4: PHI Snapshot Prompt
A5: Use this when | B5: Use after completing PHI Snapshot. Copy the dashboard scores and the primary concern into your chat alongside this prompt.
A6: Prompt | B6: You are a senior programme assurance consultant. Analyse this Programme Health Check using the supplied client metadata, overall score, RAG status, pillar scores and primary concern. Provide: 1) concise executive view, 2) top 3 risks, 3) likely root causes, 4) immediate next actions.
A8: PHI Full Prompt
A9: Use this when | B9: Use after completing PHI Full. Copy the dashboard metrics and any relevant evidence/comment rows into your chat alongside this prompt.
A10: Prompt | B10: You are a senior programme recovery expert. Analyse this full Programme Health Index assessment using the supplied client metadata, overall score, RAG status, BRI, VRI, pillar scores, evidence notes and assessor comments. Produce: executive summary, top 5 risks, recovery priorities, and a 0-30 / 31-60 / 61-90 day roadmap.

Sheet AI - ITSM
A1: AI Prompt Builder - ITSM
A2: Copy the prompt below and pair it with the relevant dashboard scores and evidence notes from the input sheet.
A4: ITSM Snapshot Prompt
A5: Use this when | B5: Use after completing ITSM Snapshot. Copy the dashboard scores and the primary concern into your chat alongside this prompt.
A6: Prompt | B6: You are a senior ITSM and service operations consultant. Analyse this Service Health Check using the supplied client metadata, overall score, RAG status, SSI, SMI, BAU readiness, pillar scores and primary concern. Provide: 1) concise service health view, 2) top 3 operational risks, 3) likely causes, 4) immediate stabilisation actions.
A8: ITSM Full Prompt
A9: Use this when | B9: Use after completing ITSM Full. Copy the dashboard metrics and any relevant evidence/comment rows into your chat alongside this prompt.
A10: Prompt | B10: You are a senior ITSM, service transition and operational resilience consultant. Analyse this full ITSM Health Index assessment using the supplied client metadata, overall score, RAG status, SSI, SMI, BAU readiness, pillar scores, evidence notes and assessor comments. Produce: executive summary, top 5 risks, stabilisation priorities, and a 0-30 / 31-60 / 61-90 day roadmap.
